Workbook

Sheet Лист1
A1: Название устройства | B1: Ссылка Цифросити | C1: Ссылка Репремиум | D1: Ссылка Девайс | E1: Цена Цифросити | F1: Цена Репремиум | G1: Цена Девайс | I1: Наименьшая цена | J1: Средняя цена | L1: НАША ЦЕНА
A2: Смартфон Apple iPhone 13 128 ГБ Темная ночь | B2: https://cifrocity.com/catalog/apple/iphone_13_13_pro_13_pro_max/apple_iphone_13_128gb_seryy/ | C2: https://mgg.stores-apple.com/catalog/apple-iphone-13-128-gb-chernyj/ | E2: 1 | F2: 47390 | I2: =MIN(E2:G2) -> 1 | J2: =AVERAGE(E2:G2) -> 23695.5 | L2: 50000
A3: Смартфон Apple iPhone 13 128 ГБ Сияющая звезда | C3: https://mgg.stores-apple.com/catalog/apple-iphone-13-128-gb-belyj/ | F3: 54390 | I3: =MIN(E3:G3) -> 54390 | J3: =AVERAGE(E3:G3) -> 54390 | L3: 50000
A4: Смартфон Apple iPhone 14 128 ГБ Темная ночь | C4: https://mgg.stores-apple.com/catalog/apple-iphone-14-128-gb-polnoch/ | F4: 50390 | I4: =MIN(E4:G4) -> 50390 | J4: =AVERAGE(E4:G4) -> 50390 | L4: 50000
A5: Смартфон Apple iPhone 15 128 ГБ Чёрный | B5: https://cifrocity.com/catalog/apple/iphone_15/apple_iphone_15_128gb_seryy/ | C5: https://mgg.stores-apple.com/catalog/apple-iphone-15-128-gb-black/ | D5: https://девайс-прайс.рф/product/apple-iphone-15/apple-iphone-15-128gb-chernyi-bez-rustore | E5: 56490 | F5: 56390 | G5: 56990 | I5: =MIN(E5:G5) -> 56390 | J5: =AVERAGE(E5:G5) -> 56623.333 | L5: 50000
A6: Смартфон Apple iPhone 15 128 ГБ Синий | B6: https://cifrocity.com/catalog/apple/iphone_15/apple_iphone_15_128gb_siniy/ | C6: https://mgg.stores-apple.com/catalog/apple-iphone-15-128-gb-siniy/ | D6: https://девайс-прайс.рф/product/apple-iphone-15/apple-iphone-15-128gb-sinii-bez-rustore | E6: 56490 | F6: 55890 | G6: 56990 | I6: =MIN(E6:G6) -> 55890 | J6: =AVERAGE(E6:G6) -> 56456.667 | L6: 50000
A7: Смартфон Apple iPhone 15 128 ГБ Зелёный | C7: https://mgg.stores-apple.com/catalog/apple-iphone-15-128-gb-green/ | F7: 59890 | I7: =MIN(E7:G7) -> 59890 | J7: =AVERAGE(E7:G7) -> 59890 | L7: 50000
A8: Смартфон Apple iPhone 15 128 ГБ Розовый | C8: https://mgg.stores-apple.com/catalog/apple-iphone-15-128-gb-pink/ | F8: 63890 | I8: =MIN(E8:G8) -> 63890 | J8: =AVERAGE(E8:G8) -> 63890 | L8: 50000
A9: Смартфон Apple iPhone 15 256 ГБ Чёрный | B9: https://cifrocity.com/catalog/apple/iphone_15/apple_iphone_15_256gb_chernyy/ | C9: https://mgg.stores-apple.com/catalog/apple-iphone-15-256-gb-black/ | D9: https://девайс-прайс.рф/product/apple-iphone-15/apple-iphone-15-256gb-chernyi-bez-rustore | E9: 66490 | F9: 66390 | G9: 66290 | I9: =MIN(E9:G9) -> 66290 | J9: =AVERAGE(E9:G9) -> 66390 | L9: 50000
A10: Смартфон Apple iPhone 15 256 ГБ Синий | B10: https://cifrocity.com/catalog/apple/iphone_15/apple_iphone_15_256gb_siniy/ | C10: https://mgg.stores-apple.com/catalog/apple-iphone-15-256-gb-siniy/ | D10: https://девайс-прайс.рф/product/apple-iphone-15/apple-iphone-15-256gb-sinii-bez-rustore | E10: 66490 | F10: 66390 | G10: 66290 | I10: =MIN(E10:G10) -> 66290 | J10: =AVERAGE(E10:G10) -> 66390 | L10: 50000
A11: Смартфон Apple iPhone 15 256 ГБ Зелёный | C11: https://mgg.stores-apple.com/catalog/apple-iphone-15-256-gb-green/ | F11: 70890 | I11: =MIN(E11:G11) -> 70890 | J11: =AVERAGE(E11:G11) -> 70890 | L11: 50000
A12: Смартфон Apple iPhone 15 256 ГБ Розовый | C12: https://mgg.stores-apple.com/catalog/apple-iphone-15-256-gb-pink/ | F12: 71390 | I12: =MIN(E12:G12) -> 71390 | J12: =AVERAGE(E12:G12) -> 71390 | L12: 50000
A13: Смартфон Apple iPhone 16 128 ГБ ультрамарин | B13: https://cifrocity.com/catalog/apple/iphone_16/apple_iphone_16_128gb_ultramarinovyy/ | C13: https://mgg.stores-apple.com/catalog/smartfon-apple-iphone-16-128-gb-ultramarin/ | D13: https://девайс-прайс.рф/product/apple-iphone-16/apple-iphone-16-128gb-ultramarin-bez-rustore | E13: 65990 | F13: 65890 | G13: 66490 | I13: =MIN(E13:G13) -> 65890 | J13: =AVERAGE(E13:G13) -> 66123.333 | L13: 50000
A14: Смартфон Apple iPhone 16 128 ГБ чёрный | B14: https://cifrocity.com/catalog/apple/iphone_16/apple_iphone_16_128gb_chernyy/ | C14: https://mgg.stores-apple.com/catalog/smartfon-apple-iphone-16-128-gb-chernyj/ | D14: https://девайс-прайс.рф/product/apple-iphone-16/apple-iphone-16-128gb-chernyi-bez-rustore | E14: 65490 | F14: 65390 | G14: 66490 | I14: =MIN(E14:G14) -> 65390 | J14: =AVERAGE(E14:G14) -> 65790 | L14: 50000
A15: Смартфон Apple iPhone 16 128 ГБ белый | B15: https://cifrocity.com/catalog/apple/iphone_16/apple_iphone_16_128gb_belyy/ | C15: https://mgg.stores-apple.com/catalog/smartfon-apple-iphone-16-128-gb-belyj/ | D15: https://девайс-прайс.рф/product/apple-iphone-16/apple-iphone-16-128gb-chernyi-bez-rustore | E15: 65490 | F15: 65390 | G15: 66490 | I15: =MIN(E15:G15) -> 65390 | J15: =AVERAGE(E15:G15) -> 65790 | L15: 50000
A16: Смартфон Apple iPhone 16 128 ГБ бирюзовый | B16: https://cifrocity.com/catalog/apple/iphone_16/apple_iphone_16_128gb_zelenyy/ | C16: https://mgg.stores-apple.com/catalog/smartfon-apple-iphone-16-128-gb-biryuzovyj/ | D16: https://девайс-прайс.рф/product/apple-iphone-16/apple-iphone-16-128gb-biriuzovyi-bez-rustore | E16: 65490 | F16: 65390 | G16: 66490 | I16: =MIN(E16:G16) -> 65390 | J16: =AVERAGE(E16:G16) -> 65790 | L16: 50000
A17: Смартфон Apple iPhone 16 128 ГБ розовый | B17: https://cifrocity.com/catalog/apple/iphone_16/apple_iphone_16_128gb_rozovyy/ | C17: https://mgg.stores-apple.com/catalog/smartfon-apple-iphone-16-128-gb-rozovyj/ | D17: https://девайс-прайс.рф/product/apple-iphone-16/apple-iphone-16-128gb-rozovyi-bez-rustore | E17: 65490 | F17: 66890 | G17: 66490 | I17: =MIN(E17:G17) -> 65490 | J17: =AVERAGE(E17:G17) -> 66290 | L17: 50000
A18: Смартфон Apple iPhone 16 256 ГБ ультрамарин | C18: https://mgg.stores-apple.com/catalog/smartfon-apple-iphone-16-256-gb-ultramarin-obmen/ | F18: 65890 | I18: =MIN(E18:G18) -> 65890 | J18: =AVERAGE(E18:G18) -> 65890 | L18: 50000
A19: Смартфон Apple iPhone 16 256 ГБ чёрный | B19: https://cifrocity.com/catalog/apple/iphone_16/apple_iphone_16_256gb_chernyy/ | C19: https://mgg.stores-apple.com/catalog/smartfon-apple-iphone-16-256-gb-chernyj-obmen/ | E19: 76990 | F19: 65890 | I19: =MIN(E19:G19) -> 65890 | J19: =AVERAGE(E19:G19) -> 71440 | L19: 50000
A20: Смартфон Apple iPhone 16 256 ГБ белый | B20: https://cifrocity.com/catalog/apple/iphone_16/apple_iphone_16_256gb_belyy/ | C20: https://mgg.stores-apple.com/catalog/smartfon-apple-iphone-16-256-gb-belyj-obmen/ | E20: 1 | F20: 65890 | I20: =MIN(E20:G20) -> 1 | J20: =AVERAGE(E20:G20) -> 32945.5 | L20: 50000
A21: Смартфон Apple iPhone 16 256 ГБ бирюзовый | B21: https://cifrocity.com/catalog/apple/iphone_16/apple_iphone_16_256gb_zelenyy/ | C21: https://mgg.stores-apple.com/catalog/smartfon-apple-iphone-16-256-gb-biryuzovyj-obmen/ | E21: 1 | F21: 65890 | I21: =MIN(E21:G21) -> 1 | J21: =AVERAGE(E21:G21) -> 32945.5 | L21: 50000
A22: Смартфон Apple iPhone 16 256 ГБ розовый | B22: https://cifrocity.com/catalog/apple/iphone_16/apple_iphone_16_256gb_rozovyy/ | C22: https://mgg.stores-apple.com/catalog/smartfon-apple-iphone-16-256-gb-rozovyj-obmen/ | E22: 76990 | F22: 65890 | I22: =MIN(E22:G22) -> 65890 | J22: =AVERAGE(E22:G22) -> 71440 | L22: 50000
A23: Смартфон Apple iPhone 16e 128 ГБ Чёрный | C23: https://mgg.stores-apple.com/catalog/smartfon-apple-iphone-16e-128-gb-chernyj/ | F23: 53390 | I23: =MIN(E23:G23) -> 53390 | J23: =AVERAGE(E23:G23) -> 53390 | L23: 50000
A24: Смартфон Apple iPhone 16e 128 ГБ Белый | C24: https://mgg.stores-apple.com/catalog/smartfon-apple-iphone-16e-128-gb-belyy/ | F24: 53390 | I24: =MIN(E24:G24) -> 53390 | J24: =AVERAGE(E24:G24) -> 53390 | L24: 50000
A25: Смартфон Apple iPhone 16e 256 ГБ Чёрный | B25: https://cifrocity.com/catalog/apple/iphone_16/apple_iphone_16e_256gb_2sim_chernyy_bez_rustore/ | C25: https://mgg.stores-apple.com/catalog/smartfon-apple-iphone-16e-256-gb-chernyj/ | E25: 53490 | F25: 58390 | I25: =MIN(E25:G25) -> 53490 | J25: =AVERAGE(E25:G25) -> 55940 | L25: 50000
A26: Смартфон Apple iPhone 16e 256 ГБ Белый | B26: https://cifrocity.com/catalog/apple/iphone_16/apple_iphone_16e_256gb_2sim_belyy_bez_rustore/ | C26: https://mgg.stores-apple.com/catalog/smartfon-apple-iphone-16e-256-gb-belyy/ | E26: 49990 | F26: 58390 | I26: =MIN(E26:G26) -> 49990 | J26: =AVERAGE(E26:G26) -> 54190 | L26: 50000
A27: Смартфон Apple iPhone 16 Plus 128 ГБ ультрамарин | C27: https://repremium.ru/magnitogorsk/catalog/smartfon_apple_iphone_16_plus_128_gb_fioletovyy/ | F27: 76390 | I27: =MIN(E27:G27) -> 76390 | J27: =AVERAGE(E27:G27) -> 76390 | L27: 50000
A28: Смартфон Apple iPhone 16 Plus 128 ГБ чёрный | C28: https://mgg.stores-apple.com/catalog/smartfon-apple-iphone-16-plus-128-gb-ultramarin/ | F28: 76390 | I28: =MIN(E28:G28) -> 76390 | J28: =AVERAGE(E28:G28) -> 76390 | L28: 50000
A29: Смартфон Apple iPhone 16 Plus 128 ГБ белый | C29: https://mgg.stores-apple.com/catalog/smartfon-apple-iphone-16-plus-128-gb-belyj/ | F29: 77390 | I29: =MIN(E29:G29) -> 77390 | J29: =AVERAGE(E29:G29) -> 77390 | L29: 50000
A30: Смартфон Apple iPhone 16 Plus 128 ГБ бирюзовый | C30: https://mgg.stores-apple.com/catalog/smartfon-apple-iphone-16-plus-128-gb-biryuzovyj/ | F30: 76390 | I30: =MIN(E30:G30) -> 76390 | J30: =AVERAGE(E30:G30) -> 76390 | L30: 50000
A31: Смартфон Apple iPhone 16 Plus 128 ГБ розовый | C31: https://mgg.stores-apple.com/catalog/smartfon-apple-iphone-16-plus-128-gb-rozovyj/ | F31: 77390 | I31: =MIN(E31:G31) -> 77390 | J31: =AVERAGE(E31:G31) -> 77390 | L31: 50000
A32: Смартфон Apple iPhone 16 Plus 256 ГБ ультрамарин | C32: https://mgg.stores-apple.com/catalog/smartfon-apple-iphone-16-plus-256-gb-ultramarin/ | F32: 83890 | I32: =MIN(E32:G32) -> 83890 | J32: =AVERAGE(E32:G32) -> 83890 | L32: 50000
A33: Смартфон Apple iPhone 16 Plus 256 ГБ чёрный | C33: https://mgg.stores-apple.com/catalog/smartfon-apple-iphone-16-plus-256-gb-chernyj/ | F33: 84890 | I33: =MIN(E33:G33) -> 84890 | J33: =AVERAGE(E33:G33) -> 84890 | L33: 50000
A34: Смартфон Apple iPhone 16 Plus 256 ГБ белый | C34: https://mgg.stores-apple.com/catalog/smartfon-apple-iphone-16-plus-256-gb-belyj/ | F34: 84390 | I34: =MIN(E34:G34) -> 84390 | J34: =AVERAGE(E34:G34) -> 84390 | L34: 50000
A35: Смартфон Apple iPhone 16 Plus 256 ГБ бирюзовый | C35: https://mgg.stores-apple.com/catalog/smartfon-apple-iphone-16-plus-256-gb-biryuzovyj/ | F35: 83890 | I35: =MIN(E35:G35) -> 83890 | J35: =AVERAGE(E35:G35) -> 83890 | L35: 50000
A36: Смартфон Apple iPhone 16 Plus 256 ГБ розовый | C36: https://mgg.stores-apple.com/catalog/smartfon-apple-iphone-16-plus-256-gb-rozovyj/ | F36: 84390 | I36: =MIN(E36:G36) -> 84390 | J36: =AVERAGE(E36:G36) -> 84390 | L36: 50000
A37: Смартфон Apple iPhone 16 Pro 128 ГБ пустынный титан | C37: https://mgg.stores-apple.com/catalog/smartfon-apple-iphone-16-pro-128-gb-pustynnyj-titan/ | F37: 98390 | I37: =MIN(E37:G37) -> 98390 | J37: =AVERAGE(E37:G37) -> 98390 | L37: 50000
A38: Смартфон Apple iPhone 16 Pro 128 ГБ белый титан | C38: https://mgg.stores-apple.com/catalog/smartfon-apple-iphone-16-pro-128-gb-belyj-titan/ | F38: 96390 | I38: =MIN(E38:G38) -> 96390 | J38: =AVERAGE(E38:G38) -> 96390 | L38: 50000
... A44: Смартфон Apple iPhone 16 Pro Max 256 ГБ черный титан | C44: https://mgg.stores-apple.com/catalog/smartfon-apple-iphone-16-pro-max-256-gb-chernyj-titan-obmen/ | F44: 98890 | I44: =MIN(E44:G44) -> 98890 | J44: =AVERAGE(E44:G44) -> 98890 | L44: 50000
A45: iPhone 17e 256 черный SIM | C45: https://mgg.stores-apple.com/catalog/smartfon_apple_iphone_17e_256_gb_chernyy/ | D45: https://девайс-прайс.рф/product/iphone-17e/apple-iphone-17e-256gb-simesim-chernyj-bez-rustore | F45: 70390 | G45: 69990 | I45: =MIN(E45:G45) -> 69990 | J45: =AVERAGE(E45:G45) -> 70190 | L45: 50000
...

Sheet Сайт
A1: ID продукта | B1: Наименование товара | C1: Цена по акции | D1: Рассрочка
A2: 2425 | B2: Смартфон Apple iPhone 11 64 ГБ Чёрный | C2: 1
A3: 2426 | B3: Смартфон Apple iPhone 11 64 ГБ Желтый | C3: 1
A4: 2427 | B4: Смартфон Apple iPhone 11 64 ГБ Зелёный | C4: 1
A5: 2428 | B5: Смартфон Apple iPhone 11 64 ГБ Красный | C5: 1
A6: 2429 | B6: Смартфон Apple iPhone 11 64 ГБ Фиолетовый | C6: 1
A7: 2430 | B7: Смартфон Apple iPhone 11 64 ГБ Белый | C7: 1
A8: 2431 | B8: Смартфон Apple iPhone 11 128 ГБ Чёрный | C8: 1
A9: 2432 | B9: Смартфон Apple iPhone 11 128 ГБ Жёлтый | C9: 1
A10: 2433 | B10: Смартфон Apple iPhone 11 128 ГБ Зелёный | C10: 1
A11: 2434 | B11: Смартфон Apple iPhone 11 128 ГБ Красный | C11: 1
A12: 2435 | B12: Смартфон Apple iPhone 11 128 ГБ Фиолетовый | C12: 1
A13: 2436 | B13: Смартфон Apple iPhone 11 128 ГБ Белый | C13: 1
... A25: 2424 | B25: Смартфон Apple iPhone 12 128 ГБ Красный | C25: 1
A26: 2395 | B26: Смартфон Apple iPhone 13 128 ГБ Темная ночь | C26: =IFERROR(VLOOKUP(B26,'Лист1'!$A:$L,12,FALSE),"") -> 50000 | D26: =ROUND((C26*1.2)/36,0) -> 1667
A27: 2396 | B27: Смартфон Apple iPhone 13 128 ГБ Сияющая звезда | C27: =IFERROR(VLOOKUP(B27,'Лист1'!$A:$L,12,FALSE),"") -> 50000 | D27: =ROUND((C27*1.2)/36,0) -> 1667
A28: 2397 | B28: Смартфон Apple iPhone 13 128 ГБ Красный | C28: 1
A29: 2398 | B29: Смартфон Apple iPhone 13 128 ГБ Розовый | C29: 1
A30: 2399 | B30: Смартфон Apple iPhone 13 128 ГБ Синий | C30: 1
A31: 2400 | B31: Смартфон Apple iPhone 13 128 ГБ Зелёный | C31: 1
A32: 2401 | B32: Смартфон Apple iPhone 13 256 ГБ Темная ночь | C32: 1
A33: 2402 | B33: Смартфон Apple iPhone 13 256 ГБ Сияющая звезда | C33: 1
A34: 2403 | B34: Смартфон Apple iPhone 13 256 ГБ Красный | C34: 1
A35: 2404 | B35: Смартфон Apple iPhone 13 256 ГБ Розовый | C35: 1
A36: 2405 | B36: Смартфон Apple iPhone 13 256 ГБ Синий | C36: 1
A37: 2406 | B37: Смартфон Apple iPhone 13 256 ГБ Зелёный | C37: 1
A38: 2407 | B38: Смартфон Apple iPhone 13 512 ГБ Темная ночь | C38: 1
A39: 2408 | B39: Смартфон Apple iPhone 13 512 ГБ Сияющая звезда | C39: 1
... A43: 2412 | B43: Смартфон Apple iPhone 13 512 ГБ Зелёный | C43: 1
A44: 2380 | B44: Смартфон Apple iPhone 14 128 ГБ Темная ночь | C44: =IFERROR(VLOOKUP(B44,'Лист1'!$A:$L,12,FALSE),"") -> 50000 | D44: =ROUND((C44*1.2)/36,0) -> 1667
A45: 2381 | B45: Смартфон Apple iPhone 14 128 ГБ Cияющая звезда | C45: 1
A46: 2382 | B46: Смартфон Apple iPhone 14 128 ГБ Синий | C46: 1
A47: 2383 | B47: Смартфон Apple iPhone 14 128 ГБ Фиолетовый | C47: 1
A48: 2384 | B48: Смартфон Apple iPhone 14 128 ГБ Красный | C48: 1
A49: 2385 | B49: Смартфон Apple iPhone 14 256 ГБ Темная ночь | C49: 1
A50: 2386 | B50: Смартфон Apple iPhone 14 256 ГБ Cияющая звезда | C50: 1
A51: 2387 | B51: Смартфон Apple iPhone 14 256 ГБ Синий | C51: 1
A52: 2388 | B52: Смартфон Apple iPhone 14 256 ГБ Фиолетовый | C52: 1
A53: 2389 | B53: Смартфон Apple iPhone 14 256 ГБ Красный | C53: 1
A54: 2390 | B54: Смартфон Apple iPhone 14 512 ГБ Темная ночь | C54: 1
...

Sheet Цены Авито АппГрейд
A1: ID | B1: Название | C1: Состояние | D1: Актуальная цена | E1: Новая цена
A2: 8478996403 | B2: iPhone 17 Pro Max, 256 ГБ, SIM + eSIM | C2: Б/У | D2: 95990
A3: 8425731761 | B3: iPhone 15 Pro Max, 256 ГБ, SIM + eSIM | C3: Б/У | D3: 54990
A4: 8421542531 | B4: Телевизор SMART TV 43" | C4: Новый | D4: 18990
A5: 8406991566 | B5: iPhone 18 Pro 256 Бургунди eSim | C5: Новый | D5: 144990 | E5: =IFERROR(VLOOKUP(B5,'Лист1'!$A:$L,12,FALSE),"") -> 50000
A6: 8367651571 | B6: Игровой ноутбук Neobieher | C6: Б/У | D6: 48990
A7: 8341657429 | B7: iPhone 13, 128 ГБ, SIM + eSIM | C7: Б/У | D7: 22990
A8: 8341582568 | B8: Телевизор SMART TV 32" | C8: Новый | D8: 12990
A9: 8341456025 | B9: iPhone 17 Pro Max, 512 ГБ, SIM + eSIM | C9: Б/У | D9: 121990
A10: 8341035435 | B10: iPhone 18 Pro Max 512 Небесно-голубой eSim | C10: Новый | D10: 184990 | E10: =IFERROR(VLOOKUP(B10,'Лист1'!$A:$L,12,FALSE),"") -> 50000
A11: 8340991761 | B11: iPhone 11, 128 ГБ, SIM + eSIM | C11: Б/У | D11: 14990
A12: 8326570265 | B12: iPhone 18 Pro Max 256 Небесно-голубой eSim | C12: Новый | D12: 174990 | E12: =IFERROR(VLOOKUP(B12,'Лист1'!$A:$L,12,FALSE),"") -> 50000
A13: 8323946523 | B13: iPhone 18 Pro Max 512 Бургунди eSim | C13: Новый | D13: 192990 | E13: =IFERROR(VLOOKUP(B13,'Лист1'!$A:$L,12,FALSE),"") -> 50000
A14: 8314848502 | B14: iPhone 18 Pro Max 256 Бургунди eSim | C14: Новый | D14: 174990 | E14: =IFERROR(VLOOKUP(B14,'Лист1'!$A:$L,12,FALSE),"") -> 50000
A15: 8314317793 | B15: iPhone 11, 64 ГБ, SIM + eSIM | C15: Б/У | D15: 13990
A16: 8304615743 | B16: Apple Watch SE2 44mm | C16: Б/У | D16: 8990
A17: 8274734574 | B17: iPhone 16e, 128 ГБ, eSIM | C17: Б/У | D17: 34990
A18: 8264857647 | B18: iPhone 15, 128 ГБ, SIM + eSIM | C18: Б/У | D18: 33990
A19: 8251624306 | B19: iPhone 18 Pro 512 Бургунди eSim | C19: Новый | D19: 169990 | E19: =IFERROR(VLOOKUP(B19,'Лист1'!$A:$L,12,FALSE),"") -> 50000
A20: 8187750769 | B20: Наушники Яндекс Дропс | C20: Новый | D20: 8490
A21: 8186978365 | B21: JBL Boombox 3 | C21: Новый | D21: 30990
A22: 8123848818 | B22: Игра NHL 26 PS5 | C22: Новый | D22: 6000
A23: 8123845669 | B23: Dyson Supersonic HD18 / Дайсон | C23: Новый | D23: 34990
A24: 8123781880 | B24: Беспроводной PowerBank Voltme 5.000 mAh | C24: Новый | D24: 4000
A25: 8123781466 | B25: Игра God Of War 3 PS4 | C25: Новый | D25: 1200
A26: 8123754401 | B26: MacBook Air 15 M5 16/1024 Рассрочка. Гарантия | C26: Новый | D26: 163990 | E26: ПОЗЖЕ
A27: 8123745418 | B27: Игра Dead Island 2 PS4 | C27: Новый | D27: 2700
A28: 8123719697 | B28: Смартфон Samsung Galaxy S26 256 ГБ белый | C28: Новый | D28: 64990 | E28: =IFERROR(VLOOKUP(B28,'Лист1'!$A:$L,12,FALSE),"") -> 64890
A29: 8123709338 | B29: Игра Robocop Rogue City PS5 | C29: Новый | D29: 2500
A30: 8123690447 | B30: Игра The Last Of Us Part 1 PS5 | C30: Новый | D30: 3300
A31: 8123675194 | B31: Адаптер питания Voltme 45W 2USB-C / USB | C31: Новый | D31: 4000
A32: 8123672082 | B32: Смартфон Samsung Galaxy S25 Plus 12/512 ГБ, зелёный | C32: Новый | D32: 71990 | E32: =IFERROR(VLOOKUP(B32,'Лист1'!$A:$L,12,FALSE),"") -> 71890
A33: 8123670325 | B33: Смартфон Samsung Galaxy S26 512 ГБ белый | C33: Новый | D33: 73990 | E33: =IFERROR(VLOOKUP(B33,'Лист1'!$A:$L,12,FALSE),"") -> 71890
A34: 8123643364 | B34: Смартфон Samsung Galaxy S25 FE 8/512 синий/белый | C34: Новый | D34: 54990 | E34: =IFERROR(VLOOKUP(B34,'Лист1'!$A:$L,12,FALSE),"") -> 57890
A35: 8123584829 | B35: MacBook Air 13 M5 24/1024 Рассрочка. Гарантия | C35: Новый | D35: 169990 | E35: ПОЗЖЕ
A36: 8123578602 | B36: Смартфон Samsung Galaxy S26 Ultra 512 ГБ серебристый | C36: Новый | D36: 93990 | E36: =IFERROR(VLOOKUP(B36,'Лист1'!$A:$L,12,FALSE),"") -> 97390
A37: 8123561642 | B37: Смарт-часы Apple Watch SE 3 44 мм, тёмная ночь | C37: Новый | D37: 25990 | E37: =IFERROR(VLOOKUP(B37,'Лист1'!$A:$L,12,FALSE),"") -> 22890
A38: 8123554725 | B38: Зарядная станция acefast 3 в 1 | C38: Новый | D38: 2990
A39: 8123546250 | B39: Смарт-часы Apple Watch SE 3 44 мм, сияющая звезда | C39: Новый | D39: 25990 | E39: =IFERROR(VLOOKUP(B39,'Лист1'!$A:$L,12,FALSE),"") -> 24890
A40: 8123543834 | B40: Игра Mortal Kombat 1 PS5 | C40: Новый | D40: 3000
...

Sheet Ценники для ТГ и ИНСТ
A1: Категория | B1: Подкатегория | C1: Модель | D1: Для бота | E1: Для бота | F1: Для бота | G1: Цена | H1: Раздел
A2: [ iPhone 13 / 14 / 15 ] | C2: iPhone 13 128 | D2: =IF(B2<>"",B2,IF(A2=A1,D1,"")) | E2: =IF(ISNUMBER(SEARCH("air",C2)),"*",IF(D2="","*",IF(ISNUMBER(SEARCH("без",D2)),"*eSIM","* SIM"))) -> * | F2: =IFERROR(__xludf.DUMMYFUNCTION("IF(ISNUMBER(SEARCH(""air"",C2)),""*air*""&REGEXEXTRACT(C2,""\d+"")&""*"",""*""&C2&""*"")"),"*iPhone 13 128*") -> *iPhone 13 128* | G2: =IFERROR(MINIFS('Лист1'!$L:$L,'Лист1'!$A:$A,F2,'Лист1'!$A:$A,E2,'Лист1'!$L:$L,"<>"),"") -> 50000 | H2: iPhone
A3: [ iPhone 13 / 14 / 15 ] | C3: iPhone 14 128 | D3: =IF(B3<>"",B3,IF(A3=A2,D2,"")) | E3: =IF(ISNUMBER(SEARCH("air",C3)),"*",IF(D3="","*",IF(ISNUMBER(SEARCH("без",D3)),"*eSIM","* SIM"))) -> * | F3: =IFERROR(__xludf.DUMMYFUNCTION("IF(ISNUMBER(SEARCH(""air"",C3)),""*air*""&REGEXEXTRACT(C3,""\d+"")&""*"",""*""&C3&""*"")"),"*iPhone 14 128*") -> *iPhone 14 128* | G3: =IFERROR(MINIFS('Лист1'!$L:$L,'Лист1'!$A:$A,F3,'Лист1'!$A:$A,E3,'Лист1'!$L:$L,"<>"),"") -> 50000 | H3: iPhone
A4: [ iPhone 13 / 14 / 15 ] | C4: iPhone 15 128 | D4: =IF(B4<>"",B4,IF(A4=A3,D3,"")) | E4: =IF(ISNUMBER(SEARCH("air",C4)),"*",IF(D4="","*",IF(ISNUMBER(SEARCH("без",D4)),"*eSIM","* SIM"))) -> * | F4: =IFERROR(__xludf.DUMMYFUNCTION("IF(ISNUMBER(SEARCH(""air"",C4)),""*air*""&REGEXEXTRACT(C4,""\d+"")&""*"",""*""&C4&""*"")"),"*iPhone 15 128*") -> *iPhone 15 128* | G4: =IFERROR(MINIFS('Лист1'!$L:$L,'Лист1'!$A:$A,F4,'Лист1'!$A:$A,E4,'Лист1'!$L:$L,"<>"),"") -> 50000 | H4: iPhone
A5: [ iPhone 13 / 14 / 15 ] | C5: iPhone 15 256 | D5: =IF(B5<>"",B5,IF(A5=A4,D4,"")) | E5: =IF(ISNUMBER(SEARCH("air",C5)),"*",IF(D5="","*",IF(ISNUMBER(SEARCH("без",D5)),"*eSIM","* SIM"))) -> * | F5: =IFERROR(__xludf.DUMMYFUNCTION("IF(ISNUMBER(SEARCH(""air"",C5)),""*air*""&REGEXEXTRACT(C5,""\d+"")&""*"",""*""&C5&""*"")"),"*iPhone 15 256*") -> *iPhone 15 256* | G5: =IFERROR(MINIFS('Лист1'!$L:$L,'Лист1'!$A:$A,F5,'Лист1'!$A:$A,E5,'Лист1'!$L:$L,"<>"),"") -> 50000 | H5: iPhone
A6: [ iPhone 13 / 14 / 15 ] | C6: iPhone 15 plus 128 | D6: =IF(B6<>"",B6,IF(A6=A5,D5,"")) | E6: =IF(ISNUMBER(SEARCH("air",C6)),"*",IF(D6="","*",IF(ISNUMBER(SEARCH("без",D6)),"*eSIM","* SIM"))) -> * | F6: =IFERROR(__xludf.DUMMYFUNCTION("IF(ISNUMBER(SEARCH(""air"",C6)),""*air*""&REGEXEXTRACT(C6,""\d+"")&""*"",""*""&C6&""*"")"),"*iPhone 15 plus 128*") -> *iPhone 15 plus 128* | G6: =IFERROR(MINIFS('Лист1'!$L:$L,'Лист1'!$A:$A,F6,'Лист1'!$A:$A,E6,'Лист1'!$L:$L,"<>"),"") -> 0 | H6: iPhone
A7: [ iPhone 13 / 14 / 15 ] | C7: iPhone 15 plus 256 | D7: =IF(B7<>"",B7,IF(A7=A6,D6,"")) | E7: =IF(ISNUMBER(SEARCH("air",C7)),"*",IF(D7="","*",IF(ISNUMBER(SEARCH("без",D7)),"*eSIM","* SIM"))) -> * | F7: =IFERROR(__xludf.DUMMYFUNCTION("IF(ISNUMBER(SEARCH(""air"",C7)),""*air*""&REGEXEXTRACT(C7,""\d+"")&""*"",""*""&C7&""*"")"),"*iPhone 15 plus 256*") -> *iPhone 15 plus 256* | G7: =IFERROR(MINIFS('Лист1'!$L:$L,'Лист1'!$A:$A,F7,'Лист1'!$A:$A,E7,'Лист1'!$L:$L,"<>"),"") -> 0 | H7: iPhone
A8: [ iPhone 16 ] | C8: iPhone 16e 128 | D8: =IF(B8<>"",B8,IF(A8=A7,D7,"")) | E8: =IF(ISNUMBER(SEARCH("air",C8)),"*",IF(D8="","*",IF(ISNUMBER(SEARCH("без",D8)),"*eSIM","* SIM"))) -> * | F8: =IFERROR(__xludf.DUMMYFUNCTION("IF(ISNUMBER(SEARCH(""air"",C8)),""*air*""&REGEXEXTRACT(C8,""\d+"")&""*"",""*""&C8&""*"")"),"*iPhone 16e 128*") -> *iPhone 16e 128* | G8: =IFERROR(MINIFS('Лист1'!$L:$L,'Лист1'!$A:$A,F8,'Лист1'!$A:$A,E8,'Лист1'!$L:$L,"<>"),"") -> 50000 | H8: iPhone
A9: [ iPhone 16 ] | C9: iPhone 16e 256 | D9: =IF(B9<>"",B9,IF(A9=A8,D8,"")) | E9: =IF(ISNUMBER(SEARCH("air",C9)),"*",IF(D9="","*",IF(ISNUMBER(SEARCH("без",D9)),"*eSIM","* SIM"))) -> * | F9: =IFERROR(__xludf.DUMMYFUNCTION("IF(ISNUMBER(SEARCH(""air"",C9)),""*air*""&REGEXEXTRACT(C9,""\d+"")&""*"",""*""&C9&""*"")"),"*iPhone 16e 256*") -> *iPhone 16e 256* | G9: =IFERROR(MINIFS('Лист1'!$L:$L,'Лист1'!$A:$A,F9,'Лист1'!$A:$A,E9,'Лист1'!$L:$L,"<>"),"") -> 50000 | H9: iPhone
A10: [ iPhone 16 ] | C10: iPhone 16 128 | D10: =IF(B10<>"",B10,IF(A10=A9,D9,"")) | E10: =IF(ISNUMBER(SEARCH("air",C10)),"*",IF(D10="","*",IF(ISNUMBER(SEARCH("без",D10)),"*eSIM","* SIM"))) -> * | F10: =IFERROR(__xludf.DUMMYFUNCTION("IF(ISNUMBER(SEARCH(""air"",C10)),""*air*""&REGEXEXTRACT(C10,""\d+"")&""*"",""*""&C10&""*"")"),"*iPhone 16 128*") -> *iPhone 16 128* | G10: =IFERROR(MINIFS('Лист1'!$L:$L,'Лист1'!$A:$A,F10,'Лист1'!$A:$A,E10,'Лист1'!$L:$L,"<>"),"") -> 50000 | H10: iPhone
A11: [ iPhone 16 ] | C11: iPhone 16 256 | D11: =IF(B11<>"",B11,IF(A11=A10,D10,"")) | E11: =IF(ISNUMBER(SEARCH("air",C11)),"*",IF(D11="","*",IF(ISNUMBER(SEARCH("без",D11)),"*eSIM","* SIM"))) -> * | F11: =IFERROR(__xludf.DUMMYFUNCTION("IF(ISNUMBER(SEARCH(""air"",C11)),""*air*""&REGEXEXTRACT(C11,""\d+"")&""*"",""*""&C11&""*"")"),"*iPhone 16 256*") -> *iPhone 16 256* | G11: =IFERROR(MINIFS('Лист1'!$L:$L,'Лист1'!$A:$A,F11,'Лист1'!$A:$A,E11,'Лист1'!$L:$L,"<>"),"") -> 50000 | H11: iPhone
A12: [ iPhone 16 ] | C12: iPhone 16 Plus 128 | D12: =IF(B12<>"",B12,IF(A12=A11,D11,"")) | E12: =IF(ISNUMBER(SEARCH("air",C12)),"*",IF(D12="","*",IF(ISNUMBER(SEARCH("без",D12)),"*eSIM","* SIM"))) -> * | F12: =IFERROR(__xludf.DUMMYFUNCTION("IF(ISNUMBER(SEARCH(""air"",C12)),""*air*""&REGEXEXTRACT(C12,""\d+"")&""*"",""*""&C12&""*"")"),"*iPhone 16 Plus 128*") -> *iPhone 16 Plus 128* | G12: =IFERROR(MINIFS('Лист1'!$L:$L,'Лист1'!$A:$A,F12,'Лист1'!$A:$A,E12,'Лист1'!$L:$L,"<>"),"") -> 50000 | H12: iPhone
A13: [ iPhone 16 ] | C13: iPhone 16 Plus 256 | D13: =IF(B13<>"",B13,IF(A13=A12,D12,"")) | E13: =IF(ISNUMBER(SEARCH("air",C13)),"*",IF(D13="","*",IF(ISNUMBER(SEARCH("без",D13)),"*eSIM","* SIM"))) -> * | F13: =IFERROR(__xludf.DUMMYFUNCTION("IF(ISNUMBER(SEARCH(""air"",C13)),""*air*""&REGEXEXTRACT(C13,""\d+"")&""*"",""*""&C13&""*"")"),"*iPhone 16 Plus 256*") -> *iPhone 16 Plus 256* | G13: =IFERROR(MINIFS('Лист1'!$L:$L,'Лист1'!$A:$A,F13,'Лист1'!$A:$A,E13,'Лист1'!$L:$L,"<>"),"") -> 50000 | H13: iPhone
A14: [ iPhone 16 ] | C14: iPhone 16 Pro 128 | D14: =IF(B14<>"",B14,IF(A14=A13,D13,"")) | E14: =IF(ISNUMBER(SEARCH("air",C14)),"*",IF(D14="","*",IF(ISNUMBER(SEARCH("без",D14)),"*eSIM","* SIM"))) -> * | F14: =IFERROR(__xludf.DUMMYFUNCTION("IF(ISNUMBER(SEARCH(""air"",C14)),""*air*""&REGEXEXTRACT(C14,""\d+"")&""*"",""*""&C14&""*"")"),"*iPhone 16 Pro 128*") -> *iPhone 16 Pro 128* | G14: =IFERROR(MINIFS('Лист1'!$L:$L,'Лист1'!$A:$A,F14,'Лист1'!$A:$A,E14,'Лист1'!$L:$L,"<>"),"") -> 50000 | H14: iPhone
A15: [ iPhone 16 ] | C15: iPhone 16 Pro Max 256 | D15: =IF(B15<>"",B15,IF(A15=A14,D14,"")) | E15: =IF(ISNUMBER(SEARCH("air",C15)),"*",IF(D15="","*",IF(ISNUMBER(SEARCH("без",D15)),"*eSIM","* SIM"))) -> * | F15: =IFERROR(__xludf.DUMMYFUNCTION("IF(ISNUMBER(SEARCH(""air"",C15)),""*air*""&REGEXEXTRACT(C15,""\d+"")&""*"",""*""&C15&""*"")"),"*iPhone 16 Pro Max 256*") -> *iPhone 16 Pro Max 256* | G15: =IFERROR(MINIFS('Лист1'!$L:$L,'Лист1'!$A:$A,F15,'Лист1'!$A:$A,E15,'Лист1'!$L:$L,"<>"),"") -> 50000 | H15: iPhone
A16: [ iPhone 17 ] | B16: Версия с физической сим-картой: | C16: iPhone 17E 256 | D16: =IF(B16<>"",B16,IF(A16=A15,D15,"")) -> Версия с физической сим-картой: | E16: =IF(ISNUMBER(SEARCH("air",C16)),"*",IF(D16="","*",IF(ISNUMBER(SEARCH("без",D16)),"*eSIM","* SIM"))) -> * SIM | F16: =IFERROR(__xludf.DUMMYFUNCTION("IF(ISNUMBER(SEARCH(""air"",C16)),""*air*""&REGEXEXTRACT(C16,""\d+"")&""*"",""*""&C16&""*"")"),"*iPhone 17E 256*") -> *iPhone 17E 256* | G16: =IFERROR(MINIFS('Лист1'!$L:$L,'Лист1'!$A:$A,F16,'Лист1'!$A:$A,E16,'Лист1'!$L:$L,"<>"),"") -> 50000 | H16: iPhone
A17: [ iPhone 17 ] | B17: Версия с физической сим-картой: | C17: iPhone 17 256 | D17: =IF(B17<>"",B17,IF(A17=A16,D16,"")) -> Версия с физической сим-картой: | E17: =IF(ISNUMBER(SEARCH("air",C17)),"*",IF(D17="","*",IF(ISNUMBER(SEARCH("без",D17)),"*eSIM","* SIM"))) -> * SIM | F17: =IFERROR(__xludf.DUMMYFUNCTION("IF(ISNUMBER(SEARCH(""air"",C17)),""*air*""&REGEXEXTRACT(C17,""\d+"")&""*"",""*""&C17&""*"")"),"*iPhone 17 256*") -> *iPhone 17 256* | G17: =IFERROR(MINIFS('Лист1'!$L:$L,'Лист1'!$A:$A,F17,'Лист1'!$A:$A,E17,'Лист1'!$L:$L,"<>"),"") -> 50000 | H17: iPhone
A18: [ iPhone 17 ] | B18: Версия с физической сим-картой: | C18: iPhone 17 512 | D18: =IF(B18<>"",B18,IF(A18=A17,D17,"")) -> Версия с физической сим-картой: | E18: =IF(ISNUMBER(SEARCH("air",C18)),"*",IF(D18="","*",IF(ISNUMBER(SEARCH("без",D18)),"*eSIM","* SIM"))) -> * SIM | F18: =IFERROR(__xludf.DUMMYFUNCTION("IF(ISNUMBER(SEARCH(""air"",C18)),""*air*""&REGEXEXTRACT(C18,""\d+"")&""*"",""*""&C18&""*"")"),"*iPhone 17 512*") -> *iPhone 17 512* | G18: =IFERROR(MINIFS('Лист1'!$L:$L,'Лист1'!$A:$A,F18,'Лист1'!$A:$A,E18,'Лист1'!$L:$L,"<>"),"") -> 50000 | H18: iPhone
A19: [ iPhone 17 ] | B19: Версия с физической сим-картой: | C19: iPhone 17 Pro 256 | D19: =IF(B19<>"",B19,IF(A19=A18,D18,"")) -> Версия с физической сим-картой: | E19: =IF(ISNUMBER(SEARCH("air",C19)),"*",IF(D19="","*",IF(ISNUMBER(SEARCH("без",D19)),"*eSIM","* SIM"))) -> * SIM | F19: =IFERROR(__xludf.DUMMYFUNCTION("IF(ISNUMBER(SEARCH(""air"",C19)),""*air*""&REGEXEXTRACT(C19,""\d+"")&""*"",""*""&C19&""*"")"),"*iPhone 17 Pro 256*") -> *iPhone 17 Pro 256* | G19: =IFERROR(MINIFS('Лист1'!$L:$L,'Лист1'!$A:$A,F19,'Лист1'!$A:$A,E19,'Лист1'!$L:$L,"<>"),"") -> 50000 | H19: iPhone
A20: [ iPhone 17 ] | B20: Версия с физической сим-картой: | C20: iPhone 17 Pro 512 | D20: =IF(B20<>"",B20,IF(A20=A19,D19,"")) -> Версия с физической сим-картой: | E20: =IF(ISNUMBER(SEARCH("air",C20)),"*",IF(D20="","*",IF(ISNUMBER(SEARCH("без",D20)),"*eSIM","* SIM"))) -> * SIM | F20: =IFERROR(__xludf.DUMMYFUNCTION("IF(ISNUMBER(SEARCH(""air"",C20)),""*air*""&REGEXEXTRACT(C20,""\d+"")&""*"",""*""&C20&""*"")"),"*iPhone 17 Pro 512*") -> *iPhone 17 Pro 512* | G20: =IFERROR(MINIFS('Лист1'!$L:$L,'Лист1'!$A:$A,F20,'Лист1'!$A:$A,E20,'Лист1'!$L:$L,"<>"),"") -> 50000 | H20: iPhone
A21: [ iPhone 17 ] | B21: Версия с физической сим-картой: | C21: iPhone 17 Pro 1024 | D21: =IF(B21<>"",B21,IF(A21=A20,D20,"")) -> Версия с физической сим-картой: | E21: =IF(ISNUMBER(SEARCH("air",C21)),"*",IF(D21="","*",IF(ISNUMBER(SEARCH("без",D21)),"*eSIM","* SIM"))) -> * SIM | F21: =IFERROR(__xludf.DUMMYFUNCTION("IF(ISNUMBER(SEARCH(""air"",C21)),""*air*""&REGEXEXTRACT(C21,""\d+"")&""*"",""*""&C21&""*"")"),"*iPhone 17 Pro 1024*") -> *iPhone 17 Pro 1024* | G21: =IFERROR(MINIFS('Лист1'!$L:$L,'Лист1'!$A:$A,F21,'Лист1'!$A:$A,E21,'Лист1'!$L:$L,"<>"),"") -> 50000 | H21: iPhone
A22: [ iPhone 17 ] | B22: Версия с физической сим-картой: | C22: iPhone 17 Pro Max 256 | D22: =IF(B22<>"",B22,IF(A22=A21,D21,"")) -> Версия с физической сим-картой: | E22: =IF(ISNUMBER(SEARCH("air",C22)),"*",IF(D22="","*",IF(ISNUMBER(SEARCH("без",D22)),"*eSIM","* SIM"))) -> * SIM | F22: =IFERROR(__xludf.DUMMYFUNCTION("IF(ISNUMBER(SEARCH(""air"",C22)),""*air*""&REGEXEXTRACT(C22,""\d+"")&""*"",""*""&C22&""*"")"),"*iPhone 17 Pro Max 256*") -> *iPhone 17 Pro Max 256* | G22: =IFERROR(MINIFS('Лист1'!$L:$L,'Лист1'!$A:$A,F22,'Лист1'!$A:$A,E22,'Лист1'!$L:$L,"<>"),"") -> 50000 | H22: iPhone
A23: [ iPhone 17 ] | B23: Версия с физической сим-картой: | C23: iPhone 17 Pro Max 512 | D23: =IF(B23<>"",B23,IF(A23=A22,D22,"")) -> Версия с физической сим-картой: | E23: =IF(ISNUMBER(SEARCH("air",C23)),"*",IF(D23="","*",IF(ISNUMBER(SEARCH("без",D23)),"*eSIM","* SIM"))) -> * SIM | F23: =IFERROR(__xludf.DUMMYFUNCTION("IF(ISNUMBER(SEARCH(""air"",C23)),""*air*""&REGEXEXTRACT(C23,""\d+"")&""*"",""*""&C23&""*"")"),"*iPhone 17 Pro Max 512*") -> *iPhone 17 Pro Max 512* | G23: =IFERROR(MINIFS('Лист1'!$L:$L,'Лист1'!$A:$A,F23,'Лист1'!$A:$A,E23,'Лист1'!$L:$L,"<>"),"") -> 50000 | H23: iPhone
A24: [ iPhone 17 ] | B24: Версия с физической сим-картой: | C24: iPhone 17 Pro Max 1024 | D24: =IF(B24<>"",B24,IF(A24=A23,D23,"")) -> Версия с физической сим-картой: | E24: =IF(ISNUMBER(SEARCH("air",C24)),"*",IF(D24="","*",IF(ISNUMBER(SEARCH("без",D24)),"*eSIM","* SIM"))) -> * SIM | F24: =IFERROR(__xludf.DUMMYFUNCTION("IF(ISNUMBER(SEARCH(""air"",C24)),""*air*""&REGEXEXTRACT(C24,""\d+"")&""*"",""*""&C24&""*"")"),"*iPhone 17 Pro Max 1024*") -> *iPhone 17 Pro Max 1024* | G24: =IFERROR(MINIFS('Лист1'!$L:$L,'Лист1'!$A:$A,F24,'Лист1'!$A:$A,E24,'Лист1'!$L:$L,"<>"),"") -> 50000 | H24: iPhone
A25: [ iPhone 17 ] | B25: Версия с физической сим-картой: | C25: iPhone 17 Pro Max 2048 | D25: =IF(B25<>"",B25,IF(A25=A24,D24,"")) -> Версия с физической сим-картой: | E25: =IF(ISNUMBER(SEARCH("air",C25)),"*",IF(D25="","*",IF(ISNUMBER(SEARCH("без",D25)),"*eSIM","* SIM"))) -> * SIM | F25: =IFERROR(__xludf.DUMMYFUNCTION("IF(ISNUMBER(SEARCH(""air"",C25)),""*air*""&REGEXEXTRACT(C25,""\d+"")&""*"",""*""&C25&""*"")"),"*iPhone 17 Pro Max 2048*") -> *iPhone 17 Pro Max 2048* | G25: =IFERROR(MINIFS('Лист1'!$L:$L,'Лист1'!$A:$A,F25,'Лист1'!$A:$A,E25,'Лист1'!$L:$L,"<>"),"") -> 50000 | H25: iPhone
A26: [ iPhone 17 ] | B26: Версия без физической сим-карты: | C26: iPhone 17 256 | D26: =IF(B26<>"",B26,IF(A26=A25,D25,"")) -> Версия без физической сим-карты: | E26: =IF(ISNUMBER(SEARCH("air",C26)),"*",IF(D26="","*",IF(ISNUMBER(SEARCH("без",D26)),"*eSIM","* SIM"))) -> *eSIM | F26: =IFERROR(__xludf.DUMMYFUNCTION("IF(ISNUMBER(SEARCH(""air"",C26)),""*air*""&REGEXEXTRACT(C26,""\d+"")&""*"",""*""&C26&""*"")"),"*iPhone 17 256*") -> *iPhone 17 256* | G26: =IFERROR(MINIFS('Лист1'!$L:$L,'Лист1'!$A:$A,F26,'Лист1'!$A:$A,E26,'Лист1'!$L:$L,"<>"),"") -> 50000 | H26: iPhone
A27: [ iPhone 17 ] | B27: Версия без физической сим-карты: | C27: iPhone 17 512 | D27: =IF(B27<>"",B27,IF(A27=A26,D26,"")) -> Версия без физической сим-карты: | E27: =IF(ISNUMBER(SEARCH("air",C27)),"*",IF(D27="","*",IF(ISNUMBER(SEARCH("без",D27)),"*eSIM","* SIM"))) -> *eSIM | F27: =IFERROR(__xludf.DUMMYFUNCTION("IF(ISNUMBER(SEARCH(""air"",C27)),""*air*""&REGEXEXTRACT(C27,""\d+"")&""*"",""*""&C27&""*"")"),"*iPhone 17 512*") -> *iPhone 17 512* | G27: =IFERROR(MINIFS('Лист1'!$L:$L,'Лист1'!$A:$A,F27,'Лист1'!$A:$A,E27,'Лист1'!$L:$L,"<>"),"") -> 50000 | H27: iPhone
A28: [ iPhone 17 ] | B28: Версия без физической сим-карты: | C28: iPhone Air 256 | D28: =IF(B28<>"",B28,IF(A28=A27,D27,"")) -> Версия без физической сим-карты: | E28: =IF(ISNUMBER(SEARCH("air",C28)),"*",IF(D28="","*",IF(ISNUMBER(SEARCH("без",D28)),"*eSIM","* SIM"))) -> * | F28: =IFERROR(__xludf.DUMMYFUNCTION("IF(ISNUMBER(SEARCH(""air"",C28)),""*air*""&REGEXEXTRACT(C28,""\d+"")&""*"",""*""&C28&""*"")"),"*air*256*") -> *air*256* | G28: =IFERROR(MINIFS('Лист1'!$L:$L,'Лист1'!$A:$A,F28,'Лист1'!$A:$A,E28,'Лист1'!$L:$L,"<>"),"") -> 50000 | H28: iPhone
A29: [ iPhone 17 ] | B29: Версия без физической сим-карты: | C29: iPhone Air 512 | D29: =IF(B29<>"",B29,IF(A29=A28,D28,"")) -> Версия без физической сим-карты: | E29: =IF(ISNUMBER(SEARCH("air",C29)),"*",IF(D29="","*",IF(ISNUMBER(SEARCH("без",D29)),"*eSIM","* SIM"))) -> * | F29: =IFERROR(__xludf.DUMMYFUNCTION("IF(ISNUMBER(SEARCH(""air"",C29)),""*air*""&REGEXEXTRACT(C29,""\d+"")&""*"",""*""&C29&""*"")"),"*air*512*") -> *air*512* | G29: =IFERROR(MINIFS('Лист1'!$L:$L,'Лист1'!$A:$A,F29,'Лист1'!$A:$A,E29,'Лист1'!$L:$L,"<>"),"") -> 50000 | H29: iPhone
A30: [ iPhone 17 ] | B30: Версия без физической сим-карты: | C30: iPhone Air 1024 | D30: =IF(B30<>"",B30,IF(A30=A29,D29,"")) -> Версия без физической сим-карты: | E30: =IF(ISNUMBER(SEARCH("air",C30)),"*",IF(D30="","*",IF(ISNUMBER(SEARCH("без",D30)),"*eSIM","* SIM"))) -> * | F30: =IFERROR(__xludf.DUMMYFUNCTION("IF(ISNUMBER(SEARCH(""air"",C30)),""*air*""&REGEXEXTRACT(C30,""\d+"")&""*"",""*""&C30&""*"")"),"*air*1024*") -> *air*1024* | G30: =IFERROR(MINIFS('Лист1'!$L:$L,'Лист1'!$A:$A,F30,'Лист1'!$A:$A,E30,'Лист1'!$L:$L,"<>"),"") -> 92390 | H30: iPhone
A31: [ iPhone 17 ] | B31: Версия без физической сим-карты: | C31: iPhone 17 Pro 256 | D31: =IF(B31<>"",B31,IF(A31=A30,D30,"")) -> Версия без физической сим-карты: | E31: =IF(ISNUMBER(SEARCH("air",C31)),"*",IF(D31="","*",IF(ISNUMBER(SEARCH("без",D31)),"*eSIM","* SIM"))) -> *eSIM | F31: =IFERROR(__xludf.DUMMYFUNCTION("IF(ISNUMBER(SEARCH(""air"",C31)),""*air*""&REGEXEXTRACT(C31,""\d+"")&""*"",""*""&C31&""*"")"),"*iPhone 17 Pro 256*") -> *iPhone 17 Pro 256* | G31: =IFERROR(MINIFS('Лист1'!$L:$L,'Лист1'!$A:$A,F31,'Лист1'!$A:$A,E31,'Лист1'!$L:$L,"<>"),"") -> 50000 | H31: iPhone
A32: [ iPhone 17 ] | B32: Версия без физической сим-карты: | C32: iPhone 17 Pro 512 | D32: =IF(B32<>"",B32,IF(A32=A31,D31,"")) -> Версия без физической сим-карты: | E32: =IF(ISNUMBER(SEARCH("air",C32)),"*",IF(D32="","*",IF(ISNUMBER(SEARCH("без",D32)),"*eSIM","* SIM"))) -> *eSIM | F32: =IFERROR(__xludf.DUMMYFUNCTION("IF(ISNUMBER(SEARCH(""air"",C32)),""*air*""&REGEXEXTRACT(C32,""\d+"")&""*"",""*""&C32&""*"")"),"*iPhone 17 Pro 512*") -> *iPhone 17 Pro 512* | G32: =IFERROR(MINIFS('Лист1'!$L:$L,'Лист1'!$A:$A,F32,'Лист1'!$A:$A,E32,'Лист1'!$L:$L,"<>"),"") -> 50000 | H32: iPhone
A33: [ iPhone 17 ] | B33: Версия без физической сим-карты: | C33: iPhone 17 Pro 1024 | D33: =IF(B33<>"",B33,IF(A33=A32,D32,"")) -> Версия без физической сим-карты: | E33: =IF(ISNUMBER(SEARCH("air",C33)),"*",IF(D33="","*",IF(ISNUMBER(SEARCH("без",D33)),"*eSIM","* SIM"))) -> *eSIM | F33: =IFERROR(__xludf.DUMMYFUNCTION("IF(ISNUMBER(SEARCH(""air"",C33)),""*air*""&REGEXEXTRACT(C33,""\d+"")&""*"",""*""&C33&""*"")"),"*iPhone 17 Pro 1024*") -> *iPhone 17 Pro 1024* | G33: =IFERROR(MINIFS('Лист1'!$L:$L,'Лист1'!$A:$A,F33,'Лист1'!$A:$A,E33,'Лист1'!$L:$L,"<>"),"") -> 50000 | H33: iPhone
A34: [ iPhone 17 ] | B34: Версия без физической сим-карты: | C34: iPhone 17 Pro Max 256 | D34: =IF(B34<>"",B34,IF(A34=A33,D33,"")) -> Версия без физической сим-карты: | E34: =IF(ISNUMBER(SEARCH("air",C34)),"*",IF(D34="","*",IF(ISNUMBER(SEARCH("без",D34)),"*eSIM","* SIM"))) -> *eSIM | F34: =IFERROR(__xludf.DUMMYFUNCTION("IF(ISNUMBER(SEARCH(""air"",C34)),""*air*""&REGEXEXTRACT(C34,""\d+"")&""*"",""*""&C34&""*"")"),"*iPhone 17 Pro Max 256*") -> *iPhone 17 Pro Max 256* | G34: =IFERROR(MINIFS('Лист1'!$L:$L,'Лист1'!$A:$A,F34,'Лист1'!$A:$A,E34,'Лист1'!$L:$L,"<>"),"") -> 50000 | H34: iPhone
A35: [ iPhone 17 ] | B35: Версия без физической сим-карты: | C35: iPhone 17 Pro Max 512 | D35: =IF(B35<>"",B35,IF(A35=A34,D34,"")) -> Версия без физической сим-карты: | E35: =IF(ISNUMBER(SEARCH("air",C35)),"*",IF(D35="","*",IF(ISNUMBER(SEARCH("без",D35)),"*eSIM","* SIM"))) -> *eSIM | F35: =IFERROR(__xludf.DUMMYFUNCTION("IF(ISNUMBER(SEARCH(""air"",C35)),""*air*""&REGEXEXTRACT(C35,""\d+"")&""*"",""*""&C35&""*"")"),"*iPhone 17 Pro Max 512*") -> *iPhone 17 Pro Max 512* | G35: =IFERROR(MINIFS('Лист1'!$L:$L,'Лист1'!$A:$A,F35,'Лист1'!$A:$A,E35,'Лист1'!$L:$L,"<>"),"") -> 50000 | H35: iPhone
A36: [ iPhone 17 ] | B36: Версия без физической сим-карты: | C36: iPhone 17 Pro Max 1024 | D36: =IF(B36<>"",B36,IF(A36=A35,D35,"")) -> Версия без физической сим-карты: | E36: =IF(ISNUMBER(SEARCH("air",C36)),"*",IF(D36="","*",IF(ISNUMBER(SEARCH("без",D36)),"*eSIM","* SIM"))) -> *eSIM | F36: =IFERROR(__xludf.DUMMYFUNCTION("IF(ISNUMBER(SEARCH(""air"",C36)),""*air*""&REGEXEXTRACT(C36,""\d+"")&""*"",""*""&C36&""*"")"),"*iPhone 17 Pro Max 1024*") -> *iPhone 17 Pro Max 1024* | G36: =IFERROR(MINIFS('Лист1'!$L:$L,'Лист1'!$A:$A,F36,'Лист1'!$A:$A,E36,'Лист1'!$L:$L,"<>"),"") -> 50000 | H36: iPhone
A37: [ iPhone 17 ] | B37: Версия без физической сим-карты: | C37: iPhone 17 Pro Max 2048 | D37: =IF(B37<>"",B37,IF(A37=A36,D36,"")) -> Версия без физической сим-карты: | E37: =IF(ISNUMBER(SEARCH("air",C37)),"*",IF(D37="","*",IF(ISNUMBER(SEARCH("без",D37)),"*eSIM","* SIM"))) -> *eSIM | F37: =IFERROR(__xludf.DUMMYFUNCTION("IF(ISNUMBER(SEARCH(""air"",C37)),""*air*""&REGEXEXTRACT(C37,""\d+"")&""*"",""*""&C37&""*"")"),"*iPhone 17 Pro Max 2048*") -> *iPhone 17 Pro Max 2048* | G37: =IFERROR(MINIFS('Лист1'!$L:$L,'Лист1'!$A:$A,F37,'Лист1'!$A:$A,E37,'Лист1'!$L:$L,"<>"),"") -> 50000 | H37: iPhone
A38: [ iPhone 18 ] | B38: Версия без физической сим-карты: | C38: iPhone 18 Pro 256 | D38: =IF(B38<>"",B38,IF(A38=A37,D37,"")) -> Версия без физической сим-карты: | E38: =IF(ISNUMBER(SEARCH("air",C38)),"*",IF(D38="","*",IF(ISNUMBER(SEARCH("без",D38)),"*eSIM","* SIM"))) -> *eSIM | F38: =IFERROR(__xludf.DUMMYFUNCTION("IF(ISNUMBER(SEARCH(""air"",C38)),""*air*""&REGEXEXTRACT(C38,""\d+"")&""*"",""*""&C38&""*"")"),"*iPhone 18 Pro 256 *") -> *iPhone 18 Pro 256 * | G38: =IFERROR(MINIFS('Лист1'!$L:$L,'Лист1'!$A:$A,F38,'Лист1'!$A:$A,E38,'Лист1'!$L:$L,"<>"),"") -> 50000 | H38: iPhone
A39: [ iPhone 18 ] | B39: Версия без физической сим-карты: | C39: iPhone 18 Pro 512 | D39: =IF(B39<>"",B39,IF(A39=A38,D38,"")) -> Версия без физической сим-карты: | E39: =IF(ISNUMBER(SEARCH("air",C39)),"*",IF(D39="","*",IF(ISNUMBER(SEARCH("без",D39)),"*eSIM","* SIM"))) -> *eSIM | F39: =IFERROR(__xludf.DUMMYFUNCTION("IF(ISNUMBER(SEARCH(""air"",C39)),""*air*""&REGEXEXTRACT(C39,""\d+"")&""*"",""*""&C39&""*"")"),"*iPhone 18 Pro 512*") -> *iPhone 18 Pro 512* | G39: =IFERROR(MINIFS('Лист1'!$L:$L,'Лист1'!$A:$A,F39,'Лист1'!$A:$A,E39,'Лист1'!$L:$L,"<>"),"") -> 50000 | H39: iPhone
A40: [ iPhone 18 ] | B40: Версия без физической сим-карты: | C40: iPhone 18 Pro 1024 | D40: =IF(B40<>"",B40,IF(A40=A39,D39,"")) -> Версия без физической сим-карты: | E40: =IF(ISNUMBER(SEARCH("air",C40)),"*",IF(D40="","*",IF(ISNUMBER(SEARCH("без",D40)),"*eSIM","* SIM"))) -> *eSIM | F40: =IFERROR(__xludf.DUMMYFUNCTION("IF(ISNUMBER(SEARCH(""air"",C40)),""*air*""&REGEXEXTRACT(C40,""\d+"")&""*"",""*""&C40&""*"")"),"*iPhone 18 Pro 1024*") -> *iPhone 18 Pro 1024* | G40: =IFERROR(MINIFS('Лист1'!$L:$L,'Лист1'!$A:$A,F40,'Лист1'!$A:$A,E40,'Лист1'!$L:$L,"<>"),"") -> 50000 | H40: iPhone
...

Sheet Ценники ВК
A1: id | B1: available | C1: name | D1: price | E1: old_price | F1: currencyId | G1: categoryId | H1: vkCategory | I1: weight | J1: dimensions | K1: ae_stock | L1: url | M1: picture | N1: description | O1: category_name

Sheet Цены Авито KingStore

Sheet mgg Каталог
A1: Категория | B1: Подкатегория | C1: Название | D1: Ссылка
A2: Apple iPhone | B2: iPhone 18 Pro Max | C2: Смартфон Apple iPhone 18 Pro Max 256 ГБ Dark Black | Чёрный eSIM | D2: https://mgg.stores-apple.com/catalog/smartfon_apple_iphone_18_pro_max_256_gb_dark_grey_tyemno_seryy_esim/
A3: Apple iPhone | B3: iPhone 18 Pro Max | C3: Смартфон Apple iPhone 18 Pro Max 256 ГБ Silver | Серебро eSIM | D3: https://mgg.stores-apple.com/catalog/smartfon_apple_iphone_18_pro_max_256_gb_silver_serebro_esim/
A4: Apple iPhone | B4: iPhone 18 Pro Max | C4: Смартфон Apple iPhone 18 Pro Max 256 ГБ Burgundy | Бургунди eSIM | D4: https://mgg.stores-apple.com/catalog/smartfon_apple_iphone_18_pro_max_256_gb_dark_cherry_tyemnaya_vishnya_esim_/
A5: Apple iPhone | B5: iPhone 18 Pro Max | C5: Смартфон Apple iPhone 18 Pro Max 256 ГБ Glacier | Ледяной | D5: https://mgg.stores-apple.com/catalog/smartfon_apple_iphone_18_pro_max_256_gb_blue_goluboy/
A6: Apple iPhone | B6: iPhone 18 Pro Max | C6: Смартфон Apple iPhone 18 Pro Max 256 ГБ Black | Чёрный | D6: https://mgg.stores-apple.com/catalog/smartfon_apple_iphone_18_pro_max_256_gb_dark_grey_tyemno_seryy/
A7: Apple iPhone | B7: iPhone 18 Pro Max | C7: Смартфон Apple iPhone 18 Pro Max 256 ГБ Silver | Серебро | D7: https://mgg.stores-apple.com/catalog/smartfon_apple_iphone_18_pro_max_256_gb_silver_serebro/
A8: Apple iPhone | B8: iPhone 18 Pro Max | C8: Смартфон Apple iPhone 18 Pro Max 256 ГБ Burgundy | Бургунди | D8: https://mgg.stores-apple.com/catalog/smartfon_apple_iphone_18_pro_max_256_gb_dark_cherry_tyemnaya_vishnya/
A9: Apple iPhone | B9: iPhone 18 Pro Max | C9: Смартфон Apple iPhone 18 Pro Max 512 ГБ Glacier | Ледяной | D9: https://mgg.stores-apple.com/catalog/smartfon_apple_iphone_18_pro_max_512_gb_blue_goluboy/
A10: Apple iPhone | B10: iPhone 18 Pro Max | C10: Смартфон Apple iPhone 18 Pro Max 512 ГБ Black | Чёрный | D10: https://mgg.stores-apple.com/catalog/smartfon_apple_iphone_18_pro_max_512_gb_dark_grey_tyemno_seryy/
A11: Apple iPhone | B11: iPhone 18 Pro Max | C11: Смартфон Apple iPhone 18 Pro Max 512 ГБ Silver | Серебро | D11: https://mgg.stores-apple.com/catalog/smartfon_apple_iphone_18_pro_max_512_gb_silver_serebro/
A12: Apple iPhone | B12: iPhone 18 Pro Max | C12: Смартфон Apple iPhone 18 Pro Max 512 ГБ Burgundy | Бургунди | D12: https://mgg.stores-apple.com/catalog/smartfon_apple_iphone_18_pro_max_512_gb_dark_cherry_tyemnaya_vishnya/
... A1554: ТВ, консоли и аудио | B1554: Микрофонная система | C1554: Микрофонная система DJI Mic 3 (2 TX + 1 RX + Charging Case) | D1554: https://mgg.stores-apple.com/catalog/mikrofonnaya_sistema_dji_mic_3_2_tx_1_rx_charging_case/

Sheet Статус
A1: Процесс | B1: Статус | C1: Проверено строк | D1: Из скольки строк | E1: Успешно цен | F1: Ошибок | G1: Обновлено | H1: Последняя строка
A2: Лист1: обновление цен | B2: готово | C2: 1448 | D2: 1448 | E2: 1463 | F2: 20 | G2: 25.09.2026 14:16:51 | H2: 1449

Sheet Лист6
A1: Смартфон Apple iPhone 17 (Sim/eSim) 256 ГБ Лавандовый
A2: Смартфон Apple iPhone 17 (Sim/eSim) 256 ГБ Чёрный
A3: Смартфон Apple iPhone 17 (Sim/eSim) 256 ГБ Белый
A4: Смартфон Apple iPhone 17 (Sim/eSim) 256 ГБ Синий
A5: Смартфон Apple iPhone 17 (Sim/eSim) 256 ГБ Зелёный
A6: Смартфон Apple iPhone 17 (eSim) 256 ГБ Лавандовый
A7: Смартфон Apple iPhone 17 (eSim) 256 ГБ Чёрный
A8: Смартфон Apple iPhone 17 (eSim) 256 ГБ Белый
A9: Смартфон Apple iPhone 17 (eSim) 256 ГБ Синий
A10: Смартфон Apple iPhone 17 (eSim) 256 ГБ Зелёный
A11: Смартфон Apple iPhone 17 (Sim/eSim) 512 ГБ Лавандовый
A12: Смартфон Apple iPhone 17 (Sim/eSim) 512 ГБ Чёрный
... A19: Смартфон Apple iPhone 17 (eSim) 512 ГБ Синий
A20: Смартфон Apple iPhone 17 (eSim) 512 ГБ Зелёный | B20: =IFERROR(__xludf.DUMMYFUNCTION("TRIM(REGEXEXTRACT(A20,""(iPhone[^(]+)\(""))&"" ""&REGEXEXTRACT(A20,""(\d+)\s*ГБ"")&"" ""&TRIM(REGEXEXTRACT(A20,""ГБ\s+(.+)$""))&"" ""&IF(REGEXMATCH(A20,""\(eSim\)""),""eSim"",""Sim"")"),"iPhone 17 512 Зелёный eSim") -> iPhone 17 512 Зелёный eSim
A21: Смартфон Apple iPhone Air 256 ГБ Синий
A22: Смартфон Apple iPhone Air 256 ГБ Чёрный
A23: Смартфон Apple iPhone Air 256 ГБ Золотой
A24: Смартфон Apple iPhone Air 256 ГБ Белый
A25: Смартфон Apple iPhone Air 512 ГБ Синий
A26: Смартфон Apple iPhone Air 512 ГБ Чёрный
A27: Смартфон Apple iPhone Air 512 ГБ Золотой
A28: Смартфон Apple iPhone Air 512 ГБ Белый
A29: Смартфон Apple iPhone Air 1 ТБ Синий
A30: Смартфон Apple iPhone Air 1 ТБ Чёрный
A31: Смартфон Apple iPhone Air 1 ТБ Золотой
A32: Смартфон Apple iPhone Air 1 ТБ Белый
... A75: Смартфон Apple iPhone 17 Pro Max (Sim/eSim) 2048 ГБ Серебристый
A76: iPhone 18 Pro 256 Черный eSim | B76: =IFERROR(__xludf.DUMMYFUNCTION("TRIM(REGEXEXTRACT(A76,""(iPhone[^(]+)\(""))&"" ""&REGEXEXTRACT(A76,""(\d+)\s*ГБ"")&"" ""&TRIM(REGEXEXTRACT(A76,""ГБ\s+(.+)$""))&"" ""&IF(REGEXMATCH(A76,""\(eSim\)""),""eSim"",""Sim"")"),"#N/A") -> #N/A
A77: iPhone 18 Pro 256 Бургунди eSim | B77: =IFERROR(__xludf.DUMMYFUNCTION("TRIM(REGEXEXTRACT(A77,""(iPhone[^(]+)\(""))&"" ""&REGEXEXTRACT(A77,""(\d+)\s*ГБ"")&"" ""&TRIM(REGEXEXTRACT(A77,""ГБ\s+(.+)$""))&"" ""&IF(REGEXMATCH(A77,""\(eSim\)""),""eSim"",""Sim"")"),"#N/A") -> #N/A
A78: iPhone 18 Pro 256 Небесно-голубой eSim | B78: =IFERROR(__xludf.DUMMYFUNCTION("TRIM(REGEXEXTRACT(A78,""(iPhone[^(]+)\(""))&"" ""&REGEXEXTRACT(A78,""(\d+)\s*ГБ"")&"" ""&TRIM(REGEXEXTRACT(A78,""ГБ\s+(.+)$""))&"" ""&IF(REGEXMATCH(A78,""\(eSim\)""),""eSim"",""Sim"")"),"#N/A") -> #N/A
A79: iPhone 18 Pro 256 Серебристый eSim | B79: =IFERROR(__xludf.DUMMYFUNCTION("TRIM(REGEXEXTRACT(A79,""(iPhone[^(]+)\(""))&"" ""&REGEXEXTRACT(A79,""(\d+)\s*ГБ"")&"" ""&TRIM(REGEXEXTRACT(A79,""ГБ\s+(.+)$""))&"" ""&IF(REGEXMATCH(A79,""\(eSim\)""),""eSim"",""Sim"")"),"#N/A") -> #N/A
A80: iPhone 18 Pro 512 Бургунди eSim | B80: =IFERROR(__xludf.DUMMYFUNCTION("TRIM(REGEXEXTRACT(A80,""(iPhone[^(]+)\(""))&"" ""&REGEXEXTRACT(A80,""(\d+)\s*ГБ"")&"" ""&TRIM(REGEXEXTRACT(A80,""ГБ\s+(.+)$""))&"" ""&IF(REGEXMATCH(A80,""\(eSim\)""),""eSim"",""Sim"")"),"#N/A") -> #N/A
A81: iPhone 18 Pro 512 Небесно-голубой eSim | B81: =IFERROR(__xludf.DUMMYFUNCTION("TRIM(REGEXEXTRACT(A81,""(iPhone[^(]+)\(""))&"" ""&REGEXEXTRACT(A81,""(\d+)\s*ГБ"")&"" ""&TRIM(REGEXEXTRACT(A81,""ГБ\s+(.+)$""))&"" ""&IF(REGEXMATCH(A81,""\(eSim\)""),""eSim"",""Sim"")"),"#N/A") -> #N/A
A82: iPhone 18 Pro 512 Серебристый eSim | B82: =IFERROR(__xludf.DUMMYFUNCTION("TRIM(REGEXEXTRACT(A82,""(iPhone[^(]+)\(""))&"" ""&REGEXEXTRACT(A82,""(\d+)\s*ГБ"")&"" ""&TRIM(REGEXEXTRACT(A82,""ГБ\s+(.+)$""))&"" ""&IF(REGEXMATCH(A82,""\(eSim\)""),""eSim"",""Sim"")"),"#N/A") -> #N/A
A83: iPhone 18 Pro 512 Черный eSim | B83: =IFERROR(__xludf.DUMMYFUNCTION("TRIM(REGEXEXTRACT(A83,""(iPhone[^(]+)\(""))&"" ""&REGEXEXTRACT(A83,""(\d+)\s*ГБ"")&"" ""&TRIM(REGEXEXTRACT(A83,""ГБ\s+(.+)$""))&"" ""&IF(REGEXMATCH(A83,""\(eSim\)""),""eSim"",""Sim"")"),"#N/A") -> #N/A
A84: Смартфон Apple iPhone 18 Pro (eSim) 1024 ГБ Бургунди | B84: =IFERROR(__xludf.DUMMYFUNCTION("TRIM(REGEXEXTRACT(A84,""(iPhone[^(]+)\(""))&"" ""&REGEXEXTRACT(A84,""(\d+)\s*ГБ"")&"" ""&TRIM(REGEXEXTRACT(A84,""ГБ\s+(.+)$""))&"" ""&IF(REGEXMATCH(A84,""\(eSim\)""),""eSim"",""Sim"")"),"iPhone 18 Pro 1024 Бургунди eSim") -> iPhone 18 Pro 1024 Бургунди eSim | D84: iPhone 18 Pro 1024 Бургунди eSim
A85: Смартфон Apple iPhone 18 Pro (eSim) 1024 ГБ Небесно-голубой | B85: =IFERROR(__xludf.DUMMYFUNCTION("TRIM(REGEXEXTRACT(A85,""(iPhone[^(]+)\(""))&"" ""&REGEXEXTRACT(A85,""(\d+)\s*ГБ"")&"" ""&TRIM(REGEXEXTRACT(A85,""ГБ\s+(.+)$""))&"" ""&IF(REGEXMATCH(A85,""\(eSim\)""),""eSim"",""Sim"")"),"iPhone 18 Pro 1024 Небесно-голубой eSim") -> iPhone 18 Pro 1024 Небесно-голубой eSim | D85: iPhone 18 Pro 1024 Небесно-голубой eSim
A86: Смартфон Apple iPhone 18 Pro (eSim) 1024 ГБ Серебристый | B86: =IFERROR(__xludf.DUMMYFUNCTION("TRIM(REGEXEXTRACT(A86,""(iPhone[^(]+)\(""))&"" ""&REGEXEXTRACT(A86,""(\d+)\s*ГБ"")&"" ""&TRIM(REGEXEXTRACT(A86,""ГБ\s+(.+)$""))&"" ""&IF(REGEXMATCH(A86,""\(eSim\)""),""eSim"",""Sim"")"),"iPhone 18 Pro 1024 Серебристый eSim") -> iPhone 18 Pro 1024 Серебристый eSim | D86: iPhone 18 Pro 1024 Серебристый eSim
A87: Смартфон Apple iPhone 18 Pro (eSim) 1024 ГБ Черный | B87: =IFERROR(__xludf.DUMMYFUNCTION("TRIM(REGEXEXTRACT(A87,""(iPhone[^(]+)\(""))&"" ""&REGEXEXTRACT(A87,""(\d+)\s*ГБ"")&"" ""&TRIM(REGEXEXTRACT(A87,""ГБ\s+(.+)$""))&"" ""&IF(REGEXMATCH(A87,""\(eSim\)""),""eSim"",""Sim"")"),"iPhone 18 Pro 1024 Черный eSim") -> iPhone 18 Pro 1024 Черный eSim | D87: iPhone 18 Pro 1024 Черный eSim
A88: Смартфон Apple iPhone 18 Pro (eSim) 2048 ГБ Бургунди | B88: =IFERROR(__xludf.DUMMYFUNCTION("TRIM(REGEXEXTRACT(A88,""(iPhone[^(]+)\(""))&"" ""&REGEXEXTRACT(A88,""(\d+)\s*ГБ"")&"" ""&TRIM(REGEXEXTRACT(A88,""ГБ\s+(.+)$""))&"" ""&IF(REGEXMATCH(A88,""\(eSim\)""),""eSim"",""Sim"")"),"iPhone 18 Pro 2048 Бургунди eSim") -> iPhone 18 Pro 2048 Бургунди eSim | D88: iPhone 18 Pro 2048 Бургунди eSim
...
